Workbook

Sheet Inputs
A1: Inputs (given, with sources)
A4: Input | B4: Value | G4: Unit | H4: Source
A5: Base-year (FY26) net sales, excluding businesses being sold (EABL) | B5: 18505.5 | G5: USD m | H5: Diageo Form 20-F FY26 (SEC accession 0001628280-26-057529, filed 18 Aug 2026): net sales 19,643 less EABL FY26 net revenue KES 145.96bn / 128.32 KES per USD (Yahoo KES=X FY26 average) = 1,137.5. EABL figure from press reports of EABL's FY26 results, 6 Aug 2026
A6: Base operating margin before exceptionals (ex-EABL) | B6: 0.29358 | G6: % | H6: Diageo Form 20-F FY26 (SEC accession 0001628280-26-057529, filed 18 Aug 2026): operating profit before exceptionals 5,683 less EABL EBIT KES 32.1bn / 128.32 = 250.2, divided by ex-EABL net sales
A7: Savings flow-through (share of savings kept as profit) | B7: 0.46 | G7: % | H7: PM decision 12 Oct 2026 (briefs/DGE.yaml): calibrated so FY27-29 profit growth hits the low end of 'mid-single-digit' guidance (Diageo Capital Markets Day, 6-K of 6 Aug 2026 (SEC accession 0001654954-26-007324))
A8: Tax rate | B8: 0.243 | G8: % | H8: Diageo Form 20-F FY26 (SEC accession 0001628280-26-057529, filed 18 Aug 2026) p.22: tax rate before exceptional items, FY26
A9: Depreciation & amortisation (D&A), % of sales | B9: 0.03377 | G9: % | H9: FY22-FY26 D&A (excl. impairment) / net sales, 5 years summed; 20-F XBRL
A10: Capital expenditure (capex), % of sales | B10: 0.07106 | G10: % | H10: FY22-FY26 purchase of PP&E and software / net sales, 5 years summed; 20-F cash flow statements
A11: Net working capital (NWC), % of sales | B11: 0.37576 | G11: % | H11: Diageo Form 20-F FY26 (SEC accession 0001628280-26-057529, filed 18 Aug 2026) balance sheet: (inventories incl. maturing 10,529 + receivables 3,277 - payables 6,425) / net sales 19,643
A13: Year-by-year inputs | B13: FY27 | C13: FY28 | D13: FY29 | E13: FY30 | F13: FY31
A14: Organic sales growth | B14: 0 | C14: 0.015 | D14: 0.025 | E14: 0.02 | F14: 0.02 | G14: % | H14: FY27 0%, FY28 1.5%, FY29 2.5%: low end of guidance (Diageo Capital Markets Day, 6-K of 6 Aug 2026 (SEC accession 0001654954-26-007324): FY27 'broadly flat', FY27-29 'low-single-digit, accelerating'). FY30-31 2.0%: PM decision 15 Oct 2026
A15: Cost savings achieved so far (cumulative run-rate) | B15: 377.5 | C15: 962.5 | D15: 1000 | E15: 1000 | F15: 1000 | G15: USD m | H15: Diageo Capital Markets Day, 6-K of 6 Aug 2026 (SEC accession 0001654954-26-007324): c.$1bn = $850m operating framework (c.40% in FY27) + $150m supply chain (c.25% in FY27); FY28 supply-chain phasing of 75% is the desk's assumption
A16: Discount rate (WACC) inputs
A17: Risk-free rate (US 10-year Treasury yield) | B17: 0.0522 | G17: % | H17: FRED series DGS10, 8 Oct 2026
A18: Equity risk premium (ERP) | B18: 0.042 | G18: % | H18: PM decision 15 Oct 2026: Damodaran implied ERP for the S&P 500, 4.20% at 1 Oct 2026 (evidence: audit-2026-10-15/erp-evidence.md)
A19: Unlevered beta (global alcoholic beverages, corrected for cash) | B19: 0.725 | G19: x | H19: Damodaran betaGlobal.xls (updated 5 Jan 2026), 'Alcoholic Beverage', 217 firms: unlevered beta corrected for cash
A20: Credit spread over the risk-free rate | B20: 0.01 | G20: % | H20: PM rule 12 Oct 2026; FRED ICE BofA A (0.69%) and BBB (1.02%) US corporate spreads, 8 Oct 2026. 20-F: leverage 'broadly consistent with an A-band credit rating'
A21: Net debt incl. leases, 30 June 2026 | B21: 20482 | G21: USD m | H21: Diageo Form 20-F FY26 (SEC accession 0001628280-26-057529, filed 18 Aug 2026) note 17 p.187: net borrowings 20,482 (includes lease liabilities 685)
A22: Ordinary shares, diluted | B22: 2231 | G22: m | H22: Diageo Form 20-F FY26 (SEC accession 0001628280-26-057529, filed 18 Aug 2026): 2,432m issued - 208m own shares (note 18(c)) + 7m dilutive shares (EPS note). Ordinary shares, NOT ADRs (1 ADR = 4 shares)
A23: Share price, 12 Oct 2026 close | B23: 1673 | G23: pence (GBp) | H23: Yahoo Finance DGE.L close, 12 Oct 2026
A24: Exchange rate, USD per GBP | B24: 1.3234 | G24: USD per GBP | H24: FRED series DEXUSUK, 2 Oct 2026
A25: Terminal value inputs
A26: Terminal growth (forever, after FY31) | B26: 0.02 | G26: % | H26: PM decision 12 Oct 2026 (briefs/DGE.yaml): below nominal GDP; US 10-year breakeven inflation 2.35% (FRED T10YIE, 8 Oct 2026)
A27: Return on new invested capital after FY31 (RONIC) | B27: 0.134 | G27: % | H27: PM decision 13 Oct 2026: Diageo's FY26 ROIC, Diageo Form 20-F FY26 (SEC accession 0001628280-26-057529, filed 18 Aug 2026) KPI table (lowest in 4 years)
A28: Equity bridge inputs
A29: Minorities' share of enterprise value | B29: 0.02566 | G29: % | H29: Diageo Form 20-F FY26 (SEC accession 0001628280-26-057529, filed 18 Aug 2026) p.210: profit before exceptionals attributable to non-controlling interests 227, less 35% x EABL EBIT 250.2, divided by ex-EABL operating profit 5,432.8
A30: Associates (mainly 34% of Moet Hennessy) | B30: 5284 | G30: USD m | H30: Diageo Form 20-F FY26 (SEC accession 0001628280-26-057529, filed 18 Aug 2026) note 'Investments in associates': Moet Hennessy 5,107 + others 177
A31: Disposal proceeds not yet received | B31: 3318.3 | G31: USD m | H31: EABL sale to Asahi c.$2.3bn (Diageo Form 20-F FY26 (SEC accession 0001628280-26-057529, filed 18 Aug 2026) p.85) + 57.21% of USL's RCB sale, c.$1.78bn (press, 24 Mar 2026). Gross, before tax
A32: Restructuring cash still to pay | B32: 850 | G32: USD m | H32: Diageo Capital Markets Day, 6-K of 6 Aug 2026 (SEC accession 0001654954-26-007324): c.$800m + c.$50m exceptional cash costs in FY27
A33: Pension deficit | B33: 0 | G33: USD m | H33: Diageo Form 20-F FY26 (SEC accession 0001628280-26-057529, filed 18 Aug 2026): net pension SURPLUS of 627, so 0 under the brief's rule
A34: Years from 30 June 2026 to the 12 Oct 2026 price date | B34: 0.2822 | G34: years | H34: 103 days / 365
A35: Dividends gone ex between 30 June and 12 Oct 2026 | B35: 0 | G35: USD m | H35: Diageo Form 20-F FY26 (SEC accession 0001628280-26-057529, filed 18 Aug 2026): final dividend goes ex on 15 Oct 2026, after the price date, so 0
A36: Rating rule
A37: BUY if upside is above | B37: 0.15 | G37: % | H37: PM rating policy (brief)
A38: SELL if upside is below | B38: -0.1 | G38: % | H38: PM rating policy (brief)

Sheet Sales & EBIT
A1: Sales and EBIT
B4: FY26 base | C4: FY27 | D4: FY28 | E4: FY29 | F4: FY30 | G4: FY31
A5: Organic sales growth | C5: =Inputs!B14 -> 0 | D5: =Inputs!C14 -> 0.015 | E5: =Inputs!D14 -> 0.025 | F5: =Inputs!E14 -> 0.02 | G5: =Inputs!F14 -> 0.02
A6: Net sales | B6: =Inputs!B5 -> 18505.5 | C6: =B6*(1+C5) -> 18505.5 | D6: =C6*(1+D5) -> 18783.082 | E6: =D6*(1+E5) -> 19252.66 | F6: =E6*(1+F5) -> 19637.713 | G6: =F6*(1+G5) -> 20030.467
A7: Cost savings run-rate (cumulative) | C7: =Inputs!B15 -> 377.5 | D7: =Inputs!C15 -> 962.5 | E7: =Inputs!D15 -> 1000 | F7: =Inputs!E15 -> 1000 | G7: =Inputs!F15 -> 1000
A8: Savings kept as profit | C8: =C7*Inputs!$B$7 -> 173.65 | D8: =D7*Inputs!$B$7 -> 442.75 | E8: =E7*Inputs!$B$7 -> 460 | F8: =F7*Inputs!$B$7 -> 460 | G8: =G7*Inputs!$B$7 -> 460
A9: EBIT (operating profit) | C9: =C6*Inputs!$B$6+C8 -> 5606.4947 | D9: =D6*Inputs!$B$6+D8 -> 5957.0874 | E9: =E6*Inputs!$B$6+E8 -> 6112.1958 | F9: =F6*Inputs!$B$6+F8 -> 6225.2397 | G9: =G6*Inputs!$B$6+G8 -> 6340.5445
A10: EBIT margin | C10: =C9/C6 -> 0.3029637 | D10: =D9/D6 -> 0.31715174 | E10: =E9/E6 -> 0.3174728 | F10: =F9/F6 -> 0.31700432 | G10: =G9/G6 -> 0.31654502

Sheet Free cash flow
A1: Unlevered free cash flow
C4: FY27 | D4: FY28 | E4: FY29 | F4: FY30 | G4: FY31
A5: EBIT | C5: ='Sales & EBIT'!C9 -> 5606.4947 | D5: ='Sales & EBIT'!D9 -> 5957.0874 | E5: ='Sales & EBIT'!E9 -> 6112.1958 | F5: ='Sales & EBIT'!F9 -> 6225.2397 | G5: ='Sales & EBIT'!G9 -> 6340.5445
A6: Tax on EBIT | C6: =C5*Inputs!$B$8 -> 1362.3782 | D6: =D5*Inputs!$B$8 -> 1447.5722 | E6: =E5*Inputs!$B$8 -> 1485.2636 | F6: =F5*Inputs!$B$8 -> 1512.7332 | G6: =G5*Inputs!$B$8 -> 1540.7523
A7: NOPAT (net operating profit after tax) | C7: =C5-C6 -> 4244.1165 | D7: =D5-D6 -> 4509.5151 | E7: =E5-E6 -> 4626.9322 | F7: =F5-F6 -> 4712.5065 | G7: =G5-G6 -> 4799.7922
A8: Add back: D&A | C8: ='Sales & EBIT'!C6*Inputs!$B$9 -> 624.93074 | D8: ='Sales & EBIT'!D6*Inputs!$B$9 -> 634.3047 | E8: ='Sales & EBIT'!E6*Inputs!$B$9 -> 650.16231 | F8: ='Sales & EBIT'!F6*Inputs!$B$9 -> 663.16556 | G8: ='Sales & EBIT'!G6*Inputs!$B$9 -> 676.42887
A9: Less: capex | C9: ='Sales & EBIT'!C6*Inputs!$B$10 -> 1315.0008 | D9: ='Sales & EBIT'!D6*Inputs!$B$10 -> 1334.7258 | E9: ='Sales & EBIT'!E6*Inputs!$B$10 -> 1368.094 | F9: ='Sales & EBIT'!F6*Inputs!$B$10 -> 1395.4559 | G9: ='Sales & EBIT'!G6*Inputs!$B$10 -> 1423.365
A10: Less: increase in net working capital | C10: =('Sales & EBIT'!C6-'Sales & EBIT'!B6)*Inputs!$B$11 -> 0 | D10: =('Sales & EBIT'!D6-'Sales & EBIT'!C6)*Inputs!$B$11 -> 104.3044 | E10: =('Sales & EBIT'!E6-'Sales & EBIT'!D6)*Inputs!$B$11 -> 176.44828 | F10: =('Sales & EBIT'!F6-'Sales & EBIT'!E6)*Inputs!$B$11 -> 144.68759 | G10: =('Sales & EBIT'!G6-'Sales & EBIT'!F6)*Inputs!$B$11 -> 147.58134
A11: Unlevered free cash flow (UFCF) | C11: =C7+C8-C9-C10 -> 3554.0464 | D11: =D7+D8-D9-D10 -> 3704.7896 | E11: =E7+E8-E9-E10 -> 3732.5523 | F11: =F7+F8-F9-F10 -> 3835.5286 | G11: =G7+G8-G9-G10 -> 3905.2747

Sheet WACC
A1: Discount rate (WACC)
A4: Step 3: WACC | B4: Your answer
A5: Market value of equity (market cap), USD m | B5: =Inputs!B22*(Inputs!B23/100)*Inputs!B24 -> 49395.415
A6: Net debt, USD m | B6: =Inputs!B21 -> 20482
A7: Debt weight D / (D + E) | B7: =B6/(B5+B6) -> 0.2931133
A8: Equity weight E / (D + E) | B8: =1-B7 -> 0.7068867
A9: Debt-to-equity ratio D / E | B9: =B6/B5 -> 0.41465387
A10: Levered (equity) beta | B10: =Inputs!B19*(1+(1-Inputs!B8)*B9) -> 0.95257241
A11: Cost of equity (CAPM) | B11: =Inputs!B17+B10*Inputs!B18 -> 0.092208041
A12: Pre-tax cost of debt | B12: =Inputs!B17+Inputs!B20 -> 0.0622
A13: After-tax cost of debt | B13: =B12*(1-Inputs!B8) -> 0.0470854
A14: WACC | B14: =B8*B11+B7*B13 -> 0.078981995

Sheet Valuation
A4: The dials
A5: WACC shift (leave at 0; the Data Table uses it) | B5: 0
A6: Terminal growth shift (leave at 0; the Data Table uses it) | B6: 0
A7: WACC used | B7: =WACC!B14+B5 -> 0.078981995
A8: Terminal growth used | B8: =Inputs!B26+B6 -> 0.02
A10: Step 4: Terminal value (value of everything after FY31) | B10: Your answer
A11: FY31 NOPAT | B11: ='Free cash flow'!G7 -> 4799.7922
A12: Terminal-year (FY32) NOPAT | B12: =B11*(1+B8) -> 4895.788
A13: Reinvestment rate | B13: =B8/Inputs!B27 -> 0.14925373
A14: Terminal-year free cash flow | B14: =B12*(1-B13) -> 4165.0734
A15: Terminal value (Gordon growth) | B15: =B14/(B7-B8) -> 70616.015
A17: Step 5: Discounting to 30 June 2026 (mid-year convention) | C17: FY27 | D17: FY28 | E17: FY29 | F17: FY30 | G17: FY31
A18: Unlevered free cash flow | C18: ='Free cash flow'!C11 -> 3554.0464 | D18: ='Free cash flow'!D11 -> 3704.7896 | E18: ='Free cash flow'!E11 -> 3732.5523 | F18: ='Free cash flow'!F11 -> 3835.5286 | G18: ='Free cash flow'!G11 -> 3905.2747
A19: Discount period (years from 30 June 2026) | C19: 0.5 | D19: 1.5 | E19: 2.5 | F19: 3.5 | G19: 4.5
A20: Discount factor | C20: =1/(1+$B$7)^C19 -> 0.96270428 | D20: =1/(1+$B$7)^D19 -> 0.89223387 | E20: =1/(1+$B$7)^E19 -> 0.82692192 | F20: =1/(1+$B$7)^F19 -> 0.76639085 | G20: =1/(1+$B$7)^G19 -> 0.71029067
A21: Present value of FCF | C21: =C18*C20 -> 3421.4957 | D21: =D18*D20 -> 3305.5387 | E21: =E18*E20 -> 3086.5293 | F21: =F18*F20 -> 2939.514 | G21: =G18*G20 -> 2773.8802
A22: Sum of present values of FCF | B22: =SUM(C21:G21) -> 15526.958
A23: Present value of terminal value | B23: =B15*G20 -> 50157.896
A24: Enterprise value (EV) | B24: =B22+B23 -> 65684.854
A25: Terminal value share of EV | B25: =B23/B24 -> 0.76361434
A39: Step 6: Equity bridge (enterprise value to equity value) | B39: Your answer
A40: Enterprise value | B40: =B24 -> 65684.854
A41: Less: net debt (incl. leases) | B41: =Inputs!B21 -> 20482
A42: Less: minority interests | B42: =Inputs!B29*B40 -> 1685.4734
A43: Less: restructuring cash still to pay | B43: =Inputs!B32 -> 850
A44: Less: pension deficit | B44: =Inputs!B33 -> 0
A45: Plus: associates | B45: =Inputs!B30 -> 5284
A46: Plus: disposal proceeds to come | B46: =Inputs!B31 -> 3318.3
A47: Equity value at 30 June 2026 | B47: =B40-B41-B42-B43-B44+B45+B46 -> 51269.681
A48: Equity value at 12 Oct 2026 (price date) | B48: =B47*(1+WACC!B11)^Inputs!B34-Inputs!B35 -> 52561.819
A50: Step 7: Value per share and rating | B50: Your answer
A51: Value per share (USD) | B51: =B48/Inputs!B22 -> 23.559758
A52: Value per share (pence, GBp) | B52: =B51/Inputs!B24*100 -> 1780.2446
A53: Upside vs share price | B53: =B52/Inputs!B23-1 -> 0.064103198
A54: Rating | B54: =IF(B53>Inputs!B37,"BUY",IF(B53<Inputs!B38,"SELL","HOLD"))
C58: Terminal growth shift (across) / WACC shift
B59: =B52 -> 1780.2446 | C59: -0.005 | D59: 0 | E59: 0.005 | F59: 0.01
A60: WACC = 6.90% | B60: -0.01 | C60: =(((((('Free cash flow'!C11/(1+(WACC!$B$14+$B60))^C19)+('Free cash flow'!D11/(1+(WACC!$B$14+$B60))^D19)+('Free cash flow'!E11/(1+(WACC!$B$14+$B60))^E19)+('Free cash flow'!F11/(1+(WACC!$B$14+$B60))^F19)+('Free cash flow'!G11/(1+(WACC!$B$14+$B60))^G19))+(('Free cash flow'!$G$7*(1+(Inputs!$B$26+C$59))*(1-(Inputs!$B$26+C$59)/Inputs!$B$27)/((WACC!$B$14+$B60)-(Inputs!$B$26+C$59)))/(1+(WACC!$B$14+$B60))^$G$19))-Inputs!$B$21-Inputs!$B$29*((('Free cash flow'!C11/(1+(WACC!$B$14+$B60))^C19)+('Free cash flow'!D11/(1+(WACC!$B$14+$B60))^D19)+('Free cash flow'!E11/(1+(WACC!$B$14+$B60))^E19)+('Free cash flow'!F11/(1+(WACC!$B$14+$B60))^F19)+('Free cash flow'!G11/(1+(WACC!$B$14+$B60))^G19))+(('Free cash flow'!$G$7*(1+(Inputs!$B$26+C$59))*(1-(Inputs!$B$26+C$59)/Inputs!$B$27)/((WACC!$B$14+$B60)-(Inputs!$B$26+C$59)))/(1+(WACC!$B$14+$B60))^$G$19))-Inputs!$B$32-Inputs!$B$33+Inputs!$B$30+Inputs!$B$31)*(1+WACC!$B$11)^Inputs!$B$34-Inputs!$B$35)/Inputs!$B$22/Inputs!$B$24*100) -> 2103.5515 | D60: =(((((('Free cash flow'!C11/(1+(WACC!$B$14+$B60))^C19)+('Free cash flow'!D11/(1+(WACC!$B$14+$B60))^D19)+('Free cash flow'!E11/(1+(WACC!$B$14+$B60))^E19)+('Free cash flow'!F11/(1+(WACC!$B$14+$B60))^F19)+('Free cash flow'!G11/(1+(WACC!$B$14+$B60))^G19))+(('Free cash flow'!$G$7*(1+(Inputs!$B$26+D$59))*(1-(Inputs!$B$26+D$59)/Inputs!$B$27)/((WACC!$B$14+$B60)-(Inputs!$B$26+D$59)))/(1+(WACC!$B$14+$B60))^$G$19))-Inputs!$B$21-Inputs!$B$29*((('Free cash flow'!C11/(1+(WACC!$B$14+$B60))^C19)+('Free cash flow'!D11/(1+(WACC!$B$14+$B60))^D19)+('Free cash flow'!E11/(1+(WACC!$B$14+$B60))^E19)+('Free cash flow'!F11/(1+(WACC!$B$14+$B60))^F19)+('Free cash flow'!G11/(1+(WACC!$B$14+$B60))^G19))+(('Free cash flow'!$G$7*(1+(Inputs!$B$26+D$59))*(1-(Inputs!$B$26+D$59)/Inputs!$B$27)/((WACC!$B$14+$B60)-(Inputs!$B$26+D$59)))/(1+(WACC!$B$14+$B60))^$G$19))-Inputs!$B$32-Inputs!$B$33+Inputs!$B$30+Inputs!$B$31)*(1+WACC!$B$11)^Inputs!$B$34-Inputs!$B$35)/Inputs!$B$22/Inputs!$B$24*100) -> 2226.0088 | E60: =(((((('Free cash flow'!C11/(1+(WACC!$B$14+$B60))^C19)+('Free cash flow'!D11/(1+(WACC!$B$14+$B60))^D19)+('Free cash flow'!E11/(1+(WACC!$B$14+$B60))^E19)+('Free cash flow'!F11/(1+(WACC!$B$14+$B60))^F19)+('Free cash flow'!G11/(1+(WACC!$B$14+$B60))^G19))+(('Free cash flow'!$G$7*(1+(Inputs!$B$26+E$59))*(1-(Inputs!$B$26+E$59)/Inputs!$B$27)/((WACC!$B$14+$B60)-(Inputs!$B$26+E$59)))/(1+(WACC!$B$14+$B60))^$G$19))-Inputs!$B$21-Inputs!$B$29*((('Free cash flow'!C11/(1+(WACC!$B$14+$B60))^C19)+('Free cash flow'!D11/(1+(WACC!$B$14+$B60))^D19)+('Free cash flow'!E11/(1+(WACC!$B$14+$B60))^E19)+('Free cash flow'!F11/(1+(WACC!$B$14+$B60))^F19)+('Free cash flow'!G11/(1+(WACC!$B$14+$B60))^G19))+(('Free cash flow'!$G$7*(1+(Inputs!$B$26+E$59))*(1-(Inputs!$B$26+E$59)/Inputs!$B$27)/((WACC!$B$14+$B60)-(Inputs!$B$26+E$59)))/(1+(WACC!$B$14+$B60))^$G$19))-Inputs!$B$32-Inputs!$B$33+Inputs!$B$30+Inputs!$B$31)*(1+WACC!$B$11)^Inputs!$B$34-Inputs!$B$35)/Inputs!$B$22/Inputs!$B$24*100) -> 2375.2883 | F60: =(((((('Free cash flow'!C11/(1+(WACC!$B$14+$B60))^C19)+('Free cash flow'!D11/(1+(WACC!$B$14+$B60))^D19)+('Free cash flow'!E11/(1+(WACC!$B$14+$B60))^E19)+('Free cash flow'!F11/(1+(WACC!$B$14+$B60))^F19)+('Free cash flow'!G11/(1+(WACC!$B$14+$B60))^G19))+(('Free cash flow'!$G$7*(1+(Inputs!$B$26+F$59))*(1-(Inputs!$B$26+F$59)/Inputs!$B$27)/((WACC!$B$14+$B60)-(Inputs!$B$26+F$59)))/(1+(WACC!$B$14+$B60))^$G$19))-Inputs!$B$21-Inputs!$B$29*((('Free cash flow'!C11/(1+(WACC!$B$14+$B60))^C19)+('Free cash flow'!D11/(1+(WACC!$B$14+$B60))^D19)+('Free cash flow'!E11/(1+(WACC!$B$14+$B60))^E19)+('Free cash flow'!F11/(1+(WACC!$B$14+$B60))^F19)+('Free cash flow'!G11/(1+(WACC!$B$14+$B60))^G19))+(('Free cash flow'!$G$7*(1+(Inputs!$B$26+F$59))*(1-(Inputs!$B$26+F$59)/Inputs!$B$27)/((WACC!$B$14+$B60)-(Inputs!$B$26+F$59)))/(1+(WACC!$B$14+$B60))^$G$19))-Inputs!$B$32-Inputs!$B$33+Inputs!$B$30+Inputs!$B$31)*(1+WACC!$B$11)^Inputs!$B$34-Inputs!$B$35)/Inputs!$B$22/Inputs!$B$24*100) -> 2561.711
A61: WACC = 7.40% | B61: -0.005 | C61: =(((((('Free cash flow'!C11/(1+(WACC!$B$14+$B61))^C19)+('Free cash flow'!D11/(1+(WACC!$B$14+$B61))^D19)+('Free cash flow'!E11/(1+(WACC!$B$14+$B61))^E19)+('Free cash flow'!F11/(1+(WACC!$B$14+$B61))^F19)+('Free cash flow'!G11/(1+(WACC!$B$14+$B61))^G19))+(('Free cash flow'!$G$7*(1+(Inputs!$B$26+C$59))*(1-(Inputs!$B$26+C$59)/Inputs!$B$27)/((WACC!$B$14+$B61)-(Inputs!$B$26+C$59)))/(1+(WACC!$B$14+$B61))^$G$19))-Inputs!$B$21-Inputs!$B$29*((('Free cash flow'!C11/(1+(WACC!$B$14+$B61))^C19)+('Free cash flow'!D11/(1+(WACC!$B$14+$B61))^D19)+('Free cash flow'!E11/(1+(WACC!$B$14+$B61))^E19)+('Free cash flow'!F11/(1+(WACC!$B$14+$B61))^F19)+('Free cash flow'!G11/(1+(WACC!$B$14+$B61))^G19))+(('Free cash flow'!$G$7*(1+(Inputs!$B$26+C$59))*(1-(Inputs!$B$26+C$59)/Inputs!$B$27)/((WACC!$B$14+$B61)-(Inputs!$B$26+C$59)))/(1+(WACC!$B$14+$B61))^$G$19))-Inputs!$B$32-Inputs!$B$33+Inputs!$B$30+Inputs!$B$31)*(1+WACC!$B$11)^Inputs!$B$34-Inputs!$B$35)/Inputs!$B$22/Inputs!$B$24*100) -> 1889.1024 | D61: =(((((('Free cash flow'!C11/(1+(WACC!$B$14+$B61))^C19)+('Free cash flow'!D11/(1+(WACC!$B$14+$B61))^D19)+('Free cash flow'!E11/(1+(WACC!$B$14+$B61))^E19)+('Free cash flow'!F11/(1+(WACC!$B$14+$B61))^F19)+('Free cash flow'!G11/(1+(WACC!$B$14+$B61))^G19))+(('Free cash flow'!$G$7*(1+(Inputs!$B$26+D$59))*(1-(Inputs!$B$26+D$59)/Inputs!$B$27)/((WACC!$B$14+$B61)-(Inputs!$B$26+D$59)))/(1+(WACC!$B$14+$B61))^$G$19))-Inputs!$B$21-Inputs!$B$29*((('Free cash flow'!C11/(1+(WACC!$B$14+$B61))^C19)+('Free cash flow'!D11/(1+(WACC!$B$14+$B61))^D19)+('Free cash flow'!E11/(1+(WACC!$B$14+$B61))^E19)+('Free cash flow'!F11/(1+(WACC!$B$14+$B61))^F19)+('Free cash flow'!G11/(1+(WACC!$B$14+$B61))^G19))+(('Free cash flow'!$G$7*(1+(Inputs!$B$26+D$59))*(1-(Inputs!$B$26+D$59)/Inputs!$B$27)/((WACC!$B$14+$B61)-(Inputs!$B$26+D$59)))/(1+(WACC!$B$14+$B61))^$G$19))-Inputs!$B$32-Inputs!$B$33+Inputs!$B$30+Inputs!$B$31)*(1+WACC!$B$11)^Inputs!$B$34-Inputs!$B$35)/Inputs!$B$22/Inputs!$B$24*100) -> 1982.4666 | E61: =(((((('Free cash flow'!C11/(1+(WACC!$B$14+$B61))^C19)+('Free cash flow'!D11/(1+(WACC!$B$14+$B61))^D19)+('Free cash flow'!E11/(1+(WACC!$B$14+$B61))^E19)+('Free cash flow'!F11/(1+(WACC!$B$14+$B61))^F19)+('Free cash flow'!G11/(1+(WACC!$B$14+$B61))^G19))+(('Free cash flow'!$G$7*(1+(Inputs!$B$26+E$59))*(1-(Inputs!$B$26+E$59)/Inputs!$B$27)/((WACC!$B$14+$B61)-(Inputs!$B$26+E$59)))/(1+(WACC!$B$14+$B61))^$G$19))-Inputs!$B$21-Inputs!$B$29*((('Free cash flow'!C11/(1+(WACC!$B$14+$B61))^C19)+('Free cash flow'!D11/(1+(WACC!$B$14+$B61))^D19)+('Free cash flow'!E11/(1+(WACC!$B$14+$B61))^E19)+('Free cash flow'!F11/(1+(WACC!$B$14+$B61))^F19)+('Free cash flow'!G11/(1+(WACC!$B$14+$B61))^G19))+(('Free cash flow'!$G$7*(1+(Inputs!$B$26+E$59))*(1-(Inputs!$B$26+E$59)/Inputs!$B$27)/((WACC!$B$14+$B61)-(Inputs!$B$26+E$59)))/(1+(WACC!$B$14+$B61))^$G$19))-Inputs!$B$32-Inputs!$B$33+Inputs!$B$30+Inputs!$B$31)*(1+WACC!$B$11)^Inputs!$B$34-Inputs!$B$35)/Inputs!$B$22/Inputs!$B$24*100) -> 2093.9944 | F61: =(((((('Free cash flow'!C11/(1+(WACC!$B$14+$B61))^C19)+('Free cash flow'!D11/(1+(WACC!$B$14+$B61))^D19)+('Free cash flow'!E11/(1+(WACC!$B$14+$B61))^E19)+('Free cash flow'!F11/(1+(WACC!$B$14+$B61))^F19)+('Free cash flow'!G11/(1+(WACC!$B$14+$B61))^G19))+(('Free cash flow'!$G$7*(1+(Inputs!$B$26+F$59))*(1-(Inputs!$B$26+F$59)/Inputs!$B$27)/((WACC!$B$14+$B61)-(Inputs!$B$26+F$59)))/(1+(WACC!$B$14+$B61))^$G$19))-Inputs!$B$21-Inputs!$B$29*((('Free cash flow'!C11/(1+(WACC!$B$14+$B61))^C19)+('Free cash flow'!D11/(1+(WACC!$B$14+$B61))^D19)+('Free cash flow'!E11/(1+(WACC!$B$14+$B61))^E19)+('Free cash flow'!F11/(1+(WACC!$B$14+$B61))^F19)+('Free cash flow'!G11/(1+(WACC!$B$14+$B61))^G19))+(('Free cash flow'!$G$7*(1+(Inputs!$B$26+F$59))*(1-(Inputs!$B$26+F$59)/Inputs!$B$27)/((WACC!$B$14+$B61)-(Inputs!$B$26+F$59)))/(1+(WACC!$B$14+$B61))^$G$19))-Inputs!$B$32-Inputs!$B$33+Inputs!$B$30+Inputs!$B$31)*(1+WACC!$B$11)^Inputs!$B$34-Inputs!$B$35)/Inputs!$B$22/Inputs!$B$24*100) -> 2229.8807
A62: WACC = 7.90% | B62: 0 | C62: =(((((('Free cash flow'!C11/(1+(WACC!$B$14+$B62))^C19)+('Free cash flow'!D11/(1+(WACC!$B$14+$B62))^D19)+('Free cash flow'!E11/(1+(WACC!$B$14+$B62))^E19)+('Free cash flow'!F11/(1+(WACC!$B$14+$B62))^F19)+('Free cash flow'!G11/(1+(WACC!$B$14+$B62))^G19))+(('Free cash flow'!$G$7*(1+(Inputs!$B$26+C$59))*(1-(Inputs!$B$26+C$59)/Inputs!$B$27)/((WACC!$B$14+$B62)-(Inputs!$B$26+C$59)))/(1+(WACC!$B$14+$B62))^$G$19))-Inputs!$B$21-Inputs!$B$29*((('Free cash flow'!C11/(1+(WACC!$B$14+$B62))^C19)+('Free cash flow'!D11/(1+(WACC!$B$14+$B62))^D19)+('Free cash flow'!E11/(1+(WACC!$B$14+$B62))^E19)+('Free cash flow'!F11/(1+(WACC!$B$14+$B62))^F19)+('Free cash flow'!G11/(1+(WACC!$B$14+$B62))^G19))+(('Free cash flow'!$G$7*(1+(Inputs!$B$26+C$59))*(1-(Inputs!$B$26+C$59)/Inputs!$B$27)/((WACC!$B$14+$B62)-(Inputs!$B$26+C$59)))/(1+(WACC!$B$14+$B62))^$G$19))-Inputs!$B$32-Inputs!$B$33+Inputs!$B$30+Inputs!$B$31)*(1+WACC!$B$11)^Inputs!$B$34-Inputs!$B$35)/Inputs!$B$22/Inputs!$B$24*100) -> 1708.2398 | D62: =(((((('Free cash flow'!C11/(1+(WACC!$B$14+$B62))^C19)+('Free cash flow'!D11/(1+(WACC!$B$14+$B62))^D19)+('Free cash flow'!E11/(1+(WACC!$B$14+$B62))^E19)+('Free cash flow'!F11/(1+(WACC!$B$14+$B62))^F19)+('Free cash flow'!G11/(1+(WACC!$B$14+$B62))^G19))+(('Free cash flow'!$G$7*(1+(Inputs!$B$26+D$59))*(1-(Inputs!$B$26+D$59)/Inputs!$B$27)/((WACC!$B$14+$B62)-(Inputs!$B$26+D$59)))/(1+(WACC!$B$14+$B62))^$G$19))-Inputs!$B$21-Inputs!$B$29*((('Free cash flow'!C11/(1+(WACC!$B$14+$B62))^C19)+('Free cash flow'!D11/(1+(WACC!$B$14+$B62))^D19)+('Free cash flow'!E11/(1+(WACC!$B$14+$B62))^E19)+('Free cash flow'!F11/(1+(WACC!$B$14+$B62))^F19)+('Free cash flow'!G11/(1+(WACC!$B$14+$B62))^G19))+(('Free cash flow'!$G$7*(1+(Inputs!$B$26+D$59))*(1-(Inputs!$B$26+D$59)/Inputs!$B$27)/((WACC!$B$14+$B62)-(Inputs!$B$26+D$59)))/(1+(WACC!$B$14+$B62))^$G$19))-Inputs!$B$32-Inputs!$B$33+Inputs!$B$30+Inputs!$B$31)*(1+WACC!$B$11)^Inputs!$B$34-Inputs!$B$35)/Inputs!$B$22/Inputs!$B$24*100) -> 1780.2446 | E62: =(((((('Free cash flow'!C11/(1+(WACC!$B$14+$B62))^C19)+('Free cash flow'!D11/(1+(WACC!$B$14+$B62))^D19)+('Free cash flow'!E11/(1+(WACC!$B$14+$B62))^E19)+('Free cash flow'!F11/(1+(WACC!$B$14+$B62))^F19)+('Free cash flow'!G11/(1+(WACC!$B$14+$B62))^G19))+(('Free cash flow'!$G$7*(1+(Inputs!$B$26+E$59))*(1-(Inputs!$B$26+E$59)/Inputs!$B$27)/((WACC!$B$14+$B62)-(Inputs!$B$26+E$59)))/(1+(WACC!$B$14+$B62))^$G$19))-Inputs!$B$21-Inputs!$B$29*((('Free cash flow'!C11/(1+(WACC!$B$14+$B62))^C19)+('Free cash flow'!D11/(1+(WACC!$B$14+$B62))^D19)+('Free cash flow'!E11/(1+(WACC!$B$14+$B62))^E19)+('Free cash flow'!F11/(1+(WACC!$B$14+$B62))^F19)+('Free cash flow'!G11/(1+(WACC!$B$14+$B62))^G19))+(('Free cash flow'!$G$7*(1+(Inputs!$B$26+E$59))*(1-(Inputs!$B$26+E$59)/Inputs!$B$27)/((WACC!$B$14+$B62)-(Inputs!$B$26+E$59)))/(1+(WACC!$B$14+$B62))^$G$19))-Inputs!$B$32-Inputs!$B$33+Inputs!$B$30+Inputs!$B$31)*(1+WACC!$B$11)^Inputs!$B$34-Inputs!$B$35)/Inputs!$B$22/Inputs!$B$24*100) -> 1864.7909 | F62: =(((((('Free cash flow'!C11/(1+(WACC!$B$14+$B62))^C19)+('Free cash flow'!D11/(1+(WACC!$B$14+$B62))^D19)+('Free cash flow'!E11/(1+(WACC!$B$14+$B62))^E19)+('Free cash flow'!F11/(1+(WACC!$B$14+$B62))^F19)+('Free cash flow'!G11/(1+(WACC!$B$14+$B62))^G19))+(('Free cash flow'!$G$7*(1+(Inputs!$B$26+F$59))*(1-(Inputs!$B$26+F$59)/Inputs!$B$27)/((WACC!$B$14+$B62)-(Inputs!$B$26+F$59)))/(1+(WACC!$B$14+$B62))^$G$19))-Inputs!$B$21-Inputs!$B$29*((('Free cash flow'!C11/(1+(WACC!$B$14+$B62))^C19)+('Free cash flow'!D11/(1+(WACC!$B$14+$B62))^D19)+('Free cash flow'!E11/(1+(WACC!$B$14+$B62))^E19)+('Free cash flow'!F11/(1+(WACC!$B$14+$B62))^F19)+('Free cash flow'!G11/(1+(WACC!$B$14+$B62))^G19))+(('Free cash flow'!$G$7*(1+(Inputs!$B$26+F$59))*(1-(Inputs!$B$26+F$59)/Inputs!$B$27)/((WACC!$B$14+$B62)-(Inputs!$B$26+F$59)))/(1+(WACC!$B$14+$B62))^$G$19))-Inputs!$B$32-Inputs!$B$33+Inputs!$B$30+Inputs!$B$31)*(1+WACC!$B$11)^Inputs!$B$34-Inputs!$B$35)/Inputs!$B$22/Inputs!$B$24*100) -> 1965.7191
...
